Workbook

Sheet Извлечение из текстов
A1: Глобально ожидаем получить на вход БЗ JSON следующего вида: { "sex": "0", "age": "35", "weight": "110", "height": "180", "BMI": "33.95", "score_scale": "9", "smoking_status": "1"}
A3: "cough":"-1" = 'отсутствует', 'жалоб на кашель не имеет', 'жалоб на кашель не предъявляет'
A4: "cough":"0" = 'кашель'
A5: "cough":"1" = 'сухой кашель', 'непродуктивный кашель', 'кашель без мокроты'
A6: "cough":"2" = 'сухой кашель', 'непродуктивный кашель', 'кашель без мокроты'
A7: "cough":"3" = 'сухой кашель', 'непродуктивный кашель', 'кашель без мокроты'
A8: "cough":"4" = 'сухой кашель', 'непродуктивный кашель', 'кашель без мокроты'
A9: "cough":"5" = 'сухой кашель', 'непродуктивный кашель', 'кашель без мокроты'
A10: "cough":"6" = 'сухой кашель', 'непродуктивный кашель', 'кашель без мокроты'
A11: "cough":"1" = 'сухой кашель', 'непродуктивный кашель', 'кашель без мокроты'
A12: "sputum":"0" = 'кашель'
A13: "sputum":"1" = 'сухой кашель', 'непродуктивный кашель', 'кашель без мокроты'
... A18: "sputum":"6" = 'сухой кашель', 'непродуктивный кашель', 'кашель без мокроты'

Sheet Скрипт activation_condition old
B1: INSERT INTO public.activation_conditions(
D2: id, name, label, kb_id, has_numeric_type, possible_numeric_range_start_point, include_start_point, possible_numeric_range_end_point, include_end_point, possible_string_values, possible_string_values_encoding, is_deleted, description, current_state, previous_state, init_state)
D3: VALUES
A5: ( | B5: id | C5: , ' | D5: name | E5: ', ' | F5: label | G5: ', | H5: kb_id | I5: , | J5: has_numeric_type | K5: , | L5: possible_numeric_range_start_point | M5: , | N5: include_start_point | O5: , | P5: possible_numeric_range_end_point | Q5: , | R5: include_end_point | S5: , '{ | T5: possible_string_values | U5: }', ' | V5: possible_string_values_encoding | W5: ', | X5: is_deleted | Y5: , ' | Z5: description | AA5: ', | AB5: current_state | AC5: , | AD5: previous_state | AE5: , | AF5: init_state | AG5: ),
A6: ( | B6: 1 | C6: , ' | D6: Кашель | E6: ', ' | F6: cough | G6: ', | H6: 1 | I6: , | J6: false | K6: , | L6: null | M6: , | N6: null | O6: , | P6: null | Q6: , | R6: null | S6: , '{ | T6: -1.6 | U6: }', ' | V6: [ {"value":"-1", "encoding":"отсутствует"}, {"value":"0", "encoding":"без уточнения"}, {"value":"1", "encoding":"непродуктивный"}, {"value":"2", "encoding":"малопродуктивный"}, {"value":"3", "encoding":"продуктивный"}, {"value":"4", "encoding":"надсадный"}, {"value":"5", "encoding":"изнуряющий"}, {"value":"6", "encoding":"с примесью крови"} ] | W6: ', | X6: false | Y6: , ' | Z6: Жалоба на кашель | AA6: ', | AC6: , | AE6: , | AG6: ),
A7: ( | B7: 2 | C7: , ' | D7: Температура тела | E7: ', ' | F7: temperature | G7: ', | H7: 1 | I7: , | J7: true | K7: , | L7: 27.00 | M7: , | N7: true | O7: , | P7: 46.50 | Q7: , | R7: true | S7: , | T7: null | U7: , | V7: null | W7: , | X7: false | Y7: , ' | Z7: Температура тела пациента | AA7: ', | AC7: , | AE7: , | AG7: ),
A8: ( | B8: 3 | C8: , ' | D8: Мокрота | E8: ', ' | F8: sputum | G8: ', | H8: 1 | I8: , | J8: false | K8: , | L8: null | M8: , | N8: null | O8: , | P8: null | Q8: , | R8: null | S8: , '{ | T8: 0.7 | U8: }', ' | V8: [ {"value":"0", "encoding":"без уточнения"}, {"value":"1", "encoding":"слизистая"}, {"value":"2", "encoding":"серозная"}, {"value":"3", "encoding":"слизисто-гнойная"}, {"value":"4", "encoding":"гнойная"}, {"value":"5", "encoding":""ржавая" мокрота"}, {"value":"6", "encoding":"серозно-геморрагическая мокрота"}, {"value":"7", "encoding":"кровавая мокрота"} ] | W8: ', | X8: false | Y8: , ' | Z8: Характер мокроты | AA8: ', | AC8: , | AE8: , | AG8: ),
A9: ( | B9: 4 | C9: , ' | D9: Боль в грудной клетке | E9: ', ' | F9: chest_pain | G9: ', | H9: 1 | I9: , | J9: false | K9: , | L9: null | M9: , | N9: null | O9: , | P9: null | Q9: , | R9: null | S9: , '{ | T9: 0.1 | U9: }', ' | V9: [ {"value":"0", "encoding":"нет"}, {"value":"1", "encoding":"есть"} ] | W9: ', | X9: false | Y9: , ' | Z9: Боль в грудной клетке | AA9: ', | AC9: , | AE9: , | AG9: ),
A10: ( | B10: 5 | C10: , ' | D10: Артралгия | E10: ', ' | F10: arthralgia | G10: ', | H10: 1 | I10: , | J10: false | K10: , | L10: null | M10: , | N10: null | O10: , | P10: null | Q10: , | R10: null | S10: , '{ | T10: 0.1 | U10: }', ' | V10: [ {"value":"0", "encoding":"нет"}, {"value":"1", "encoding":"есть"} ] | W10: ', | X10: false | Y10: , ' | Z10: Боль в суставах | AA10: ', | AC10: , | AE10: , | AG10: ),
A11: ( | B11: 6 | C11: , ' | D11: Миалгия | E11: ', ' | F11: myalgia | G11: ', | H11: 1 | I11: , | J11: false | K11: , | L11: null | M11: , | N11: null | O11: , | P11: null | Q11: , | R11: null | S11: , '{ | T11: 0.1 | U11: }', ' | V11: [ {"value":"0", "encoding":"нет"}, {"value":"1", "encoding":"есть"} ] | W11: ', | X11: false | Y11: , ' | Z11: Боль в мышцах | AA11: ', | AC11: , | AE11: , | AG11: ),
A12: ( | B12: 7 | C12: , ' | D12: Оссалгия | E12: ', ' | F12: ossalgia | G12: ', | H12: 1 | I12: , | J12: false | K12: , | L12: null | M12: , | N12: null | O12: , | P12: null | Q12: , | R12: null | S12: , '{ | T12: 0.1 | U12: }', ' | V12: [ {"value":"0", "encoding":"нет"}, {"value":"1", "encoding":"есть"} ] | W12: ', | X12: false | Y12: , ' | Z12: Боль в костях | AA12: ', | AC12: , | AE12: , | AG12: ),
A13: ( | B13: 8 | C13: , ' | D13: Боль в глазных яблоках | E13: ', ' | F13: eyeballs_pain | G13: ', | H13: 1 | I13: , | J13: false | K13: , | L13: null | M13: , | N13: null | O13: , | P13: null | Q13: , | R13: null | S13: , '{ | T13: 0.1 | U13: }', ' | V13: [ {"value":"0", "encoding":"нет"}, {"value":"1", "encoding":"есть"} ] | W13: ', | X13: false | Y13: , ' | Z13: Боль в глазных яблоках | AA13: ', | AC13: , | AE13: , | AG13: ),
A14: ( | B14: 9 | C14: , ' | D14: Конъюнктивит | E14: ', ' | F14: conjunctivitis | G14: ', | H14: 1 | I14: , | J14: false | K14: , | L14: null | M14: , | N14: null | O14: , | P14: null | Q14: , | R14: null | S14: , '{ | T14: 0.1 | U14: }', ' | V14: [ {"value":"0", "encoding":"нет"}, {"value":"1", "encoding":"есть"} ] | W14: ', | X14: false | Y14: , ' | Z14: Конъюнктивит | AA14: ', | AC14: , | AE14: , | AG14: ),
A15: ( | B15: 10 | C15: , ' | D15: Головная боль | E15: ', ' | F15: headache | G15: ', | H15: 1 | I15: , | J15: false | K15: , | L15: null | M15: , | N15: null | O15: , | P15: null | Q15: , | R15: null | S15: , '{ | T15: 0.1 | U15: }', ' | V15: [ {"value":"0", "encoding":"нет"}, {"value":"1", "encoding":"есть"} ] | W15: ', | X15: false | Y15: , ' | Z15: Головная боль | AA15: ', | AC15: , | AE15: , | AG15: ),
A16: ( | B16: 11 | C16: , ' | D16: Боль в плечевом суставе | E16: ', ' | F16: shoulder_joint_pain | G16: ', | H16: 1 | I16: , | J16: false | K16: , | L16: null | M16: , | N16: null | O16: , | P16: null | Q16: , | R16: null | S16: , '{ | T16: 0.1 | U16: }', ' | V16: [ {"value":"0", "encoding":"нет"}, {"value":"1", "encoding":"есть"} ] | W16: ', | X16: false | Y16: , | Z16: Боль в плечевом суставе | AA16: ', | AC16: , | AE16: , | AG16: ),
A17: ( | B17: 12 | C17: , ' | D17: Боль в плече | E17: ', ' | F17: shoulder_joint_pain | G17: ', | H17: 1 | I17: , | J17: false | K17: , | L17: null | M17: , | N17: null | O17: , | P17: null | Q17: , | R17: null | S17: , '{ | T17: 0.1 | U17: }', ' | V17: [ {"value":"0", "encoding":"нет"}, {"value":"1", "encoding":"есть"} ] | W17: ', | X17: false | Y17: , | Z17: Боль в плече | AA17: ', | AC17: , | AE17: , | AG17: ),
A18: ( | B18: 13 | C18: , ' | D18: Атрофия мышц предплечья | E18: ', ' | F18: muscles_forearm_atrophy | G18: ', | H18: 1 | I18: , | J18: false | K18: , | L18: null | M18: , | N18: null | O18: , | P18: null | Q18: , | R18: null | S18: , '{ | T18: 0.1 | U18: }', ' | V18: [ {"value":"0", "encoding":"нет"}, {"value":"1", "encoding":"есть"} ] | W18: ', | X18: false | Y18: , | Z18: Атрофия мышц предплечья | AA18: ', | AC18: , | AE18: , | AG18: ),
A19: ( | B19: 14 | C19: , ' | D19: Голос | E19: ', ' | F19: voice | G19: ', | H19: 1 | I19: , | J19: false | K19: , | L19: null | M19: , | N19: null | O19: , | P19: null | Q19: , | R19: null | S19: , '{ | T19: 0.4 | U19: }', ' | V19: [ {"value":"0", "encoding":"нормальный"}, {"value":"1", "encoding":"осиплый"}, {"value":"2", "encoding":"охриплый"}, {"value":"3", "encoding":"тихий"}, {"value":"4", "encoding":"потерян"} ] | W19: ', | X19: false | Y19: , | Z19: Голос | AA19: ', | AC19: , | AE19: , | AG19: ),
A20: ( | B20: 15 | C20: , ' | D20: Насморк | E20: ', ' | F20: runny_nose | G20: ', | H20: 1 | I20: , | J20: false | K20: , | L20: null | M20: , | N20: null | O20: , | P20: null | Q20: , | R20: null | S20: , '{ | T20: 0.2 | U20: }', ' | V20: [ {"value":"0", "encoding":"отсутствует"}, {"value":"1", "encoding":"заложенность носа"}, {"value":"2", "encoding":"острый ринит"} ] | W20: ', | X20: false | Y20: , | Z20: Заложенность носа | AA20: ', | AC20: , | AE20: , | AG20: ),
A21: ( | B21: 16 | C21: , ' | D21: Чихание | E21: ', ' | F21: sneezing | G21: ', | H21: 1 | I21: , | J21: false | K21: , | L21: null | M21: , | N21: null | O21: , | P21: null | Q21: , | R21: null | S21: , '{ | T21: 0.1 | U21: }', ' | V21: [ {"value":"0", "encoding":"нет"}, {"value":"1", "encoding":"есть"} ] | W21: ', | X21: false | Y21: , | AA21: ', | AC21: , | AE21: , | AG21: ),
A22: ( | B22: 17 | C22: , ' | D22: Одышка | E22: ', ' | F22: dyspnea | G22: ', | H22: 1 | I22: , | J22: false | K22: , | L22: null | M22: , | N22: null | O22: , | P22: null | Q22: , | R22: null | S22: , '{ | T22: 0.2 | U22: }', ' | V22: [ {"value":"0", "encoding:"отсутствует"}, {"value":"1", "ecoding":"при физической активности"}, {"value":"2", "encoding":"в покое"} ] | W22: ', | X22: false | Y22: , | AA22: ', | AC22: , | AE22: , | AG22: ),
A23: ( | B23: 18 | C23: , ' | D23: Пол | E23: ', ' | F23: sex | G23: ', | H23: 1 | I23: , | J23: false | K23: , | L23: null | M23: , | N23: null | O23: , | P23: null | Q23: , | R23: null | S23: , '{ | T23: -1.1 | U23: }', ' | V23: [ {"value":"-1", "encoding:"Не определён"}, {"value":"0", "ecoding":"Мужской"}, {"value":"1", "encoding":"Женский"} ] | W23: ', | X23: false | Y23: , ' | AA23: ', | AC23: , | AE23: , | AG23: ),
A24: ( | B24: 19 | C24: , ' | D24: Наличие работы | E24: ', ' | F24: employment | G24: ', | H24: 1 | I24: , | J24: false | K24: , | L24: null | M24: , | N24: null | O24: , | P24: null | Q24: , | R24: null | S24: , '{ | T24: 0.2 | U24: }', ' | V24: [ {"value":"0", "encoding:"Безработный"}, {"value":"1", "ecoding":"Работает"}, {"value":"2", "encoding":"Учащийся"} ] | W24: ', | X24: false | Y24: , ' | AA24: ', | AC24: , | AE24: , | AG24: ),
A25: ( | B25: 20 | C25: , ' | D25: Наличие МБТ в мокроте | E25: ', ' | F25: MBT_sputum | G25: ', | H25: 1 | I25: , | J25: false | K25: , | L25: null | M25: , | N25: null | O25: , | P25: null | Q25: , | R25: null | S25: , '{ | T25: 0.1 | U25: }', ' | V25: [ {"value":"0", "encoding":"нет"}, {"value":"1", "encoding":"есть"} ] | W25: ', | X25: false | Y25: , ' | AA25: ', | AC25: , | AE25: , | AG25: ),
A26: ( | B26: 21 | C26: , ' | D26: Наличие МБТ в бронхоальвеолярном лаваже | E26: ', ' | F26: MBT_lavage | G26: ', | H26: 1 | I26: , | J26: false | K26: , | L26: null | M26: , | N26: null | O26: , | P26: null | Q26: , | R26: null | S26: , '{ | T26: 0.1 | U26: }', ' | V26: [ {"value":"0", "encoding":"нет"}, {"value":"1", "encoding":"есть"} ] | W26: ', | X26: false | Y26: , | AA26: ', | AC26: , | AE26: , | AG26: ),
A27: ( | B27: 22 | C27: , ' | E27: ', ' | G27: ', | H27: 1 | I27: , | K27: , | M27: , | O27: , | Q27: , | S27: , '{ | U27: , ' | W27: ', | X27: false | Y27: , | AA27: ', | AC27: , | AE27: , | AG27: ),
A28: ( | B28: 23 | C28: , ' | E28: ', ' | G28: ', | H28: 1 | I28: , | K28: , | M28: , | O28: , | Q28: , | S28: , '{ | U28: , ' | W28: ', | X28: false | Y28: , ' | AA28: ', | AC28: , | AE28: , | AG28: ),
A29: ( | B29: 24 | C29: , ' | E29: ', ' | G29: ', | H29: 1 | I29: , | K29: , | M29: , | O29: , | Q29: , | S29: , '{ | U29: , ' | W29: ', | X29: false | Y29: , | AA29: ', | AC29: , | AE29: , | AG29: ),
A30: ( | B30: 25 | C30: , ' | E30: ', ' | G30: ', | H30: 1 | I30: , | K30: , | M30: , | O30: , | Q30: , | S30: , '{ | U30: , ' | W30: ', | X30: false | Y30: , | AA30: ', | AC30: , | AE30: , | AG30: ),
A31: ( | B31: 26 | C31: , ' | E31: ', ' | G31: ', | H31: 1 | I31: , | K31: , | M31: , | O31: , | Q31: , | S31: , '{ | U31: , ' | W31: ', | X31: false | Y31: , | AA31: ', | AC31: , | AE31: , | AG31: ),
A32: ( | B32: 27 | C32: , ' | E32: ', ' | G32: ', | H32: 1 | I32: , | K32: , | M32: , | O32: , | Q32: , | S32: , '{ | U32: , ' | W32: ', | X32: false | Y32: , | AA32: ', | AC32: , | AE32: , | AG32: ),
A33: ( | B33: 28 | C33: , ' | E33: ', ' | G33: ', | H33: 1 | I33: , | K33: , | M33: , | O33: , | Q33: , | S33: , '{ | U33: , ' | W33: ', | X33: false | Y33: , | AA33: ', | AC33: , | AE33: , | AG33: ),
A34: ( | B34: 29 | C34: , ' | E34: ', ' | G34: ', | H34: 1 | I34: , | K34: , | M34: , | O34: , | Q34: , | S34: , '{ | U34: , ' | W34: ', | X34: false | Y34: , | AA34: ', | AC34: , | AE34: , | AG34: ),
A35: ( | B35: 30 | C35: , ' | E35: ', ' | G35: ', | H35: 1 | I35: , | K35: , | M35: , | O35: , | Q35: , | S35: , '{ | U35: , ' | W35: ', | X35: false | Y35: , | AA35: ', | AC35: , | AE35: , | AG35: ),
A36: ( | B36: 31 | C36: , ' | E36: ', ' | G36: ', | H36: 1 | I36: , | K36: , | M36: , | O36: , | Q36: , | S36: , '{ | U36: , ' | W36: ', | X36: false | Y36: , | AA36: ', | AC36: , | AE36: , | AG36: ),
A37: ( | B37: 32 | C37: , ' | E37: ', ' | G37: ', | H37: 1 | I37: , | K37: , | M37: , | O37: , | Q37: , | S37: , '{ | U37: , ' | W37: ', | X37: false | Y37: , | AA37: ', | AC37: , | AE37: , | AG37: ),
A38: ( | B38: 33 | C38: , ' | E38: ', ' | G38: ', | H38: 1 | I38: , | K38: , | M38: , | O38: , | Q38: , | S38: , '{ | U38: , ' | W38: ', | X38: false | Y38: , | AA38: ', | AC38: , | AE38: , | AG38: ),
... A55: ( | B55: 50 | C55: , ' | E55: ', ' | G55: ', | H55: 1 | I55: , | K55: , | M55: , | O55: , | Q55: , | S55: , '{ | U55: , ' | W55: ', | X55: false | Y55: , | AA55: ', | AC55: , | AE55: , | AG55: ),

Sheet Скрипт node_activation_cond old
B1: INSERT INTO public.node_activation_conditions(
D2: id, node_id, activation_condition_id, numeric_range_start_point, include_start_point, numeric_range_end_point, include_end_point, string_values, is_deleted, description, current_state, init_state)
B3: VALUES
A4: ( | B4: id | C4: , | D4: node_id | E4: , | F4: activation_condition_id | G4: , | H4: numeric_range_start_point | I4: , | J4: include_start_point | K4: , | L4: numeric_range_end_point | M4: , | N4: include_end_point | O4: , '{ | P4: string_values | Q4: }', | R4: is_deleted | S4: , ' | T4: description | U4: ', | V4: current_state | W4: , | X4: init_state | Y4: ),
A5: ( | B5: 1 | C5: , | D5: --- | E5: , | F5: 1 | G5: , | H5: null | I5: , | J5: null | K5: , | L5: null | M5: , | N5: null | O5: , '{ | P5: -1 | Q5: }', | R5: false | S5: , ' | T5: отсутствует | U5: ', | V5: 2090 | W5: , | X5: 2090 | Y5: ), | Z5: =VLOOKUP(F5,'Скрипт activation_condition'!$B$6:$D$53,3,0) -> Кашель отсутсвует
A6: ( | B6: 2 | C6: , | D6: --- | E6: , | F6: 1 | G6: , | H6: null | I6: , | J6: null | K6: , | L6: null | M6: , | N6: null | O6: , '{ | P6: 0 | Q6: }', | R6: false | S6: , ' | T6: без уточнения | U6: ', | W6: , | Y6: ), | Z6: =VLOOKUP(F6,'Скрипт activation_condition'!$B$6:$D$53,3,0) -> Кашель отсутсвует
A7: ( | B7: 3 | C7: , | D7: 15 | E7: , | F7: 1 | G7: , | H7: null | I7: , | J7: null | K7: , | L7: null | M7: , | N7: null | O7: , '{ | P7: 1 | Q7: }', | R7: false | S7: , ' | T7: сухой | U7: ', | W7: , | Y7: ), | Z7: =VLOOKUP(F7,'Скрипт activation_condition'!$B$6:$D$53,3,0) -> Кашель отсутсвует
A8: ( | B8: 4 | C8: , | D8: 17 | E8: , | F8: 1 | G8: , | H8: null | I8: , | J8: null | K8: , | L8: null | M8: , | N8: null | O8: , '{ | P8: 2 | Q8: }', | R8: false | S8: , ' | T8: малопродуктивный | U8: ', | W8: , | Y8: ), | Z8: =VLOOKUP(F8,'Скрипт activation_condition'!$B$6:$D$53,3,0) -> Кашель отсутсвует
A9: ( | B9: 5 | C9: , | D9: 9 | E9: , | F9: 1 | G9: , | H9: null | I9: , | J9: null | K9: , | L9: null | M9: , | N9: null | O9: , '{ | P9: 3 | Q9: }', | R9: false | S9: , ' | T9: влажный | U9: ', | W9: , | Y9: ), | Z9: =VLOOKUP(F9,'Скрипт activation_condition'!$B$6:$D$53,3,0) -> Кашель отсутсвует
A10: ( | B10: 6 | C10: , | D10: 10 | E10: , | F10: 1 | G10: , | H10: null | I10: , | J10: null | K10: , | L10: null | M10: , | N10: null | O10: , '{ | P10: 4 | Q10: }', | R10: false | S10: , ' | T10: надсадный | U10: ', | W10: , | Y10: ), | Z10: =VLOOKUP(F10,'Скрипт activation_condition'!$B$6:$D$53,3,0) -> Кашель отсутсвует
A11: ( | B11: 7 | C11: , | D11: 18 | E11: , | F11: 1 | G11: , | H11: null | I11: , | J11: null | K11: , | L11: null | M11: , | N11: null | O11: , '{ | P11: 5 | Q11: }', | R11: false | S11: , ' | T11: изнуряющий | U11: ', | W11: , | Y11: ), | Z11: =VLOOKUP(F11,'Скрипт activation_condition'!$B$6:$D$53,3,0) -> Кашель отсутсвует
A12: ( | B12: 8 | C12: , | D12: 16 | E12: , | F12: 1 | G12: , | H12: null | I12: , | J12: null | K12: , | L12: null | M12: , | N12: null | O12: , '{ | P12: 6 | Q12: }', | R12: false | S12: , ' | T12: с кровью | U12: ', | W12: , | Y12: ), | Z12: =VLOOKUP(F12,'Скрипт activation_condition'!$B$6:$D$53,3,0) -> Кашель отсутсвует
A13: ( | B13: 9 | C13: , | D13: --- | E13: , | F13: 2 | G13: , | H13: 27.00 | I13: , | J13: true | K13: , | L13: 35.40 | M13: , | N13: true | O13: , | P13: null | Q13: , | R13: false | S13: , ' | T13: Низкая температура | U13: ', | W13: , | Y13: ), | Z13: =VLOOKUP(F13,'Скрипт activation_condition'!$B$6:$D$53,3,0) -> Кашель без уточнения
A14: ( | B14: 10 | C14: , | D14: --- | E14: , | F14: 2 | G14: , | H14: 35.50 | I14: , | J14: true | K14: , | L14: 37.00 | M14: , | N14: true | O14: , | P14: null | Q14: , | R14: false | S14: , ' | T14: Нормальная температура тела | U14: ', | W14: , | Y14: ), | Z14: =VLOOKUP(F14,'Скрипт activation_condition'!$B$6:$D$53,3,0) -> Кашель без уточнения
A15: ( | B15: 11 | C15: , | D15: 172 | E15: , | F15: 2 | G15: , | H15: 37.10 | I15: , | J15: true | K15: , | L15: 38.00 | M15: , | N15: true | O15: , | P15: null | Q15: , | R15: false | S15: , ' | T15: Субфебрильная температура тела | U15: ', | W15: , | Y15: ), | Z15: =VLOOKUP(F15,'Скрипт activation_condition'!$B$6:$D$53,3,0) -> Кашель без уточнения
A16: ( | B16: 12 | C16: , | D16: 173 | E16: , | F16: 2 | G16: , | H16: 38.10 | I16: , | J16: true | K16: , | L16: 39.50 | M16: , | N16: true | O16: , | P16: null | Q16: , | R16: false | S16: , ' | T16: Фебрильная температура тела | U16: ', | W16: , | Y16: ), | Z16: =VLOOKUP(F16,'Скрипт activation_condition'!$B$6:$D$53,3,0) -> Кашель без уточнения
A17: ( | B17: 13 | C17: , | D17: 174 | E17: , | F17: 2 | G17: , | H17: 39.60 | I17: , | J17: true | K17: , | L17: 42.00 | M17: , | N17: true | O17: , | P17: null | Q17: , | R17: false | S17: , ' | T17: Пиретическая температура тела | U17: ', | W17: , | Y17: ), | Z17: =VLOOKUP(F17,'Скрипт activation_condition'!$B$6:$D$53,3,0) -> Кашель без уточнения
A18: ( | B18: 14 | C18: , | D18: --- | E18: , | F18: 2 | G18: , | H18: 42.10 | I18: , | J18: true | K18: , | L18: 46.50 | M18: , | N18: true | O18: , | P18: null | Q18: , | R18: false | S18: , ' | T18: Гиперпирексическая температура тела | U18: ', | W18: , | Y18: ), | Z18: =VLOOKUP(F18,'Скрипт activation_condition'!$B$6:$D$53,3,0) -> Кашель без уточнения
A19: ( | B19: 15 | C19: , | D19: --- | E19: , | F19: 3 | G19: , | H19: null | I19: , | J19: null | K19: , | L19: null | M19: , | N19: null | O19: , '{ | P19: 0 | Q19: }', | R19: false | S19: , ' | T19: без уточнения | U19: ', | W19: , | Y19: ), | Z19: =VLOOKUP(F19,'Скрипт activation_condition'!$B$6:$D$53,3,0) -> Кашель непродуктивный
A20: ( | B20: 16 | C20: , | D20: 14 | E20: , | F20: 3 | G20: , | H20: null | I20: , | J20: null | K20: , | L20: null | M20: , | N20: null | O20: , '{ | P20: 1 | Q20: }', | R20: false | S20: , ' | T20: слизистая | U20: ', | W20: , | Y20: ), | Z20: =VLOOKUP(F20,'Скрипт activation_condition'!$B$6:$D$53,3,0) -> Кашель непродуктивный
A21: ( | B21: 17 | C21: , | D21: --- | E21: , | F21: 3 | G21: , | H21: null | I21: , | J21: null | K21: , | L21: null | M21: , | N21: null | O21: , '{ | P21: 2 | Q21: }', | R21: false | S21: , ' | T21: серозная | U21: ', | W21: , | Y21: ), | Z21: =VLOOKUP(F21,'Скрипт activation_condition'!$B$6:$D$53,3,0) -> Кашель непродуктивный
A22: ( | B22: 18 | C22: , | D22: 12 | E22: , | F22: 3 | G22: , | H22: null | I22: , | J22: null | K22: , | L22: null | M22: , | N22: null | O22: , '{ | P22: 3 | Q22: }', | R22: false | S22: , ' | T22: слизисто-гнойная | U22: ', | W22: , | Y22: ), | Z22: =VLOOKUP(F22,'Скрипт activation_condition'!$B$6:$D$53,3,0) -> Кашель непродуктивный
A23: ( | B23: 19 | C23: , | D23: --- | E23: , | F23: 3 | G23: , | H23: null | I23: , | J23: null | K23: , | L23: null | M23: , | N23: null | O23: , '{ | P23: 4 | Q23: }', | R23: false | S23: , ' | T23: гнойная | U23: ', | W23: , | Y23: ), | Z23: =VLOOKUP(F23,'Скрипт activation_condition'!$B$6:$D$53,3,0) -> Кашель непродуктивный
A24: ( | B24: 20 | C24: , | D24: 13 | E24: , | F24: 3 | G24: , | H24: null | I24: , | J24: null | K24: , | L24: null | M24: , | N24: null | O24: , '{ | P24: 5 | Q24: }', | R24: false | S24: , ' | T24: "ржавая" мокрота | U24: ', | W24: , | Y24: ), | Z24: =VLOOKUP(F24,'Скрипт activation_condition'!$B$6:$D$53,3,0) -> Кашель непродуктивный
A25: ( | B25: 21 | C25: , | D25: 11 | E25: , | F25: 3 | G25: , | H25: null | I25: , | J25: null | K25: , | L25: null | M25: , | N25: null | O25: , '{ | P25: 6 | Q25: }', | R25: false | S25: , ' | T25: серозно-геморрагическая | U25: ', | W25: , | Y25: ), | Z25: =VLOOKUP(F25,'Скрипт activation_condition'!$B$6:$D$53,3,0) -> Кашель непродуктивный
A26: ( | B26: 22 | C26: , | D26: --- | E26: , | F26: 3 | G26: , | H26: null | I26: , | J26: null | K26: , | L26: null | M26: , | N26: null | O26: , '{ | P26: 7 | Q26: }', | R26: false | S26: , ' | T26: кровавая мокрота | U26: ', | W26: , | Y26: ), | Z26: =VLOOKUP(F26,'Скрипт activation_condition'!$B$6:$D$53,3,0) -> Кашель непродуктивный
A27: ( | B27: 23 | C27: , | D27: 19 | E27: , | F27: 4 | G27: , | H27: null | I27: , | J27: null | K27: , | L27: null | M27: , | N27: null | O27: , '{ | P27: 1 | Q27: }', | R27: false | S27: , ' | T27: боль в грудной клетке имеется | U27: ', | W27: , | Y27: ), | Z27: =VLOOKUP(F27,'Скрипт activation_condition'!$B$6:$D$53,3,0) -> Кашель малопродуктивный
A28: ( | B28: 24 | C28: , | D28: 20 | E28: , | F28: 5 | G28: , | H28: null | I28: , | J28: null | K28: , | L28: null | M28: , | N28: null | O28: , '{ | P28: 1 | Q28: }', | R28: false | S28: , ' | T28: боль в суставах имеется | U28: ', | W28: , | Y28: ), | Z28: =VLOOKUP(F28,'Скрипт activation_condition'!$B$6:$D$53,3,0) -> Кашель продуктивный
A29: ( | B29: 25 | C29: , | D29: 21 | E29: , | F29: 6 | G29: , | H29: null | I29: , | J29: null | K29: , | L29: null | M29: , | N29: null | O29: , '{ | P29: 1 | Q29: }', | R29: false | S29: , ' | T29: боль в мышцах имеется | U29: ', | W29: , | Y29: ), | Z29: =VLOOKUP(F29,'Скрипт activation_condition'!$B$6:$D$53,3,0) -> Кашель надсадный
A30: ( | B30: 26 | C30: , | D30: 22 | E30: , | F30: 7 | G30: , | H30: null | I30: , | J30: null | K30: , | L30: null | M30: , | N30: null | O30: , '{ | P30: 1 | Q30: }', | R30: false | S30: , ' | T30: боль в костях имеется | U30: ', | W30: , | Y30: ), | Z30: =VLOOKUP(F30,'Скрипт activation_condition'!$B$6:$D$53,3,0) -> Кашель изнуряющий
A31: ( | B31: 27 | C31: , | D31: 23 | E31: , | F31: 8 | G31: , | H31: null | I31: , | J31: null | K31: , | L31: null | M31: , | N31: null | O31: , '{ | P31: 1 | Q31: }', | R31: false | S31: , ' | T31: Боль в глазных яблоках | U31: ', | W31: , | Y31: ), | Z31: =VLOOKUP(F31,'Скрипт activation_condition'!$B$6:$D$53,3,0) -> Кашель с примесью крови
A32: ( | B32: 28 | C32: , | D32: 24 | E32: , | F32: 9 | G32: , | H32: null | I32: , | J32: null | K32: , | L32: null | M32: , | N32: null | O32: , '{ | P32: 1 | Q32: }', | R32: false | S32: , ' | T32: Конъюнктивит | U32: ', | W32: , | Y32: ), | Z32: =VLOOKUP(F32,'Скрипт activation_condition'!$B$6:$D$53,3,0) -> Температура тела
A33: ( | B33: 29 | C33: , | D33: 25 | E33: , | F33: 10 | G33: , | H33: null | I33: , | J33: null | K33: , | L33: null | M33: , | N33: null | O33: , '{ | P33: 1 | Q33: }', | R33: false | S33: , ' | T33: Головная боль | U33: ', | W33: , | Y33: ), | Z33: =VLOOKUP(F33,'Скрипт activation_condition'!$B$6:$D$53,3,0) -> Мокрота
A34: ( | B34: 30 | C34: , | D34: 26 | E34: , | F34: 11 | G34: , | H34: null | I34: , | J34: null | K34: , | L34: null | M34: , | N34: null | O34: , '{ | P34: 1 | Q34: }', | R34: false | S34: , ' | T34: Боль в плечевом суставе | U34: ', | W34: , | Y34: ), | Z34: =VLOOKUP(F34,'Скрипт activation_condition'!$B$6:$D$53,3,0) -> Боль в грудной клетке
A35: ( | B35: 31 | C35: , | D35: 27 | E35: , | F35: 12 | G35: , | H35: null | I35: , | J35: null | K35: , | L35: null | M35: , | N35: null | O35: , '{ | P35: 1 | Q35: }', | R35: false | S35: , ' | T35: Боль в плече | U35: ', | W35: , | Y35: ), | Z35: =VLOOKUP(F35,'Скрипт activation_condition'!$B$6:$D$53,3,0) -> Артралгия
A36: ( | B36: 32 | C36: , | D36: 28 | E36: , | F36: 13 | G36: , | H36: null | I36: , | J36: null | K36: , | L36: null | M36: , | N36: null | O36: , '{ | P36: 1 | Q36: }', | R36: false | S36: , ' | T36: Атрофия мышц предплечья | U36: ', | W36: , | Y36: ), | Z36: =VLOOKUP(F36,'Скрипт activation_condition'!$B$6:$D$53,3,0) -> Миалгия
A37: ( | B37: 33 | C37: , | D37: --- | E37: , | F37: 14 | G37: , | H37: null | I37: , | J37: null | K37: , | L37: null | M37: , | N37: null | O37: , '{ | P37: 0 | Q37: }', | R37: false | S37: , ' | T37: Голос не изменён | U37: ', | W37: , | Y37: ), | Z37: =VLOOKUP(F37,'Скрипт activation_condition'!$B$6:$D$53,3,0) -> Оссалгия
A38: ( | B38: 34 | C38: , | D38: 30 | E38: , | F38: 14 | G38: , | H38: null | I38: , | J38: null | K38: , | L38: null | M38: , | N38: null | O38: , '{ | P38: 1 | Q38: }', | R38: false | S38: , ' | T38: Осиплый голос | U38: ', | W38: , | Y38: ), | Z38: =VLOOKUP(F38,'Скрипт activation_condition'!$B$6:$D$53,3,0) -> Оссалгия
A39: ( | B39: 35 | C39: , | D39: --- | E39: , | F39: 14 | G39: , | H39: null | I39: , | J39: null | K39: , | L39: null | M39: , | N39: null | O39: , '{ | P39: 2 | Q39: }', | R39: false | S39: , ' | T39: Охриплый голос | U39: ', | W39: , | Y39: ), | Z39: =VLOOKUP(F39,'Скрипт activation_condition'!$B$6:$D$53,3,0) -> Оссалгия
A40: ( | B40: 36 | C40: , | D40: --- | E40: , | F40: 14 | G40: , | H40: null | I40: , | J40: null | K40: , | L40: null | M40: , | N40: null | O40: , '{ | P40: 3 | Q40: }', | R40: false | S40: , ' | T40: Тихий голос | U40: ', | W40: , | Y40: ), | Z40: =VLOOKUP(F40,'Скрипт activation_condition'!$B$6:$D$53,3,0) -> Оссалгия
...

Sheet Примечания
A1: Выбрать 3 болезни для диф диагноза
A2: Сказать НА какие выбрала
A4: Разделы для БЗ
A5: 1. Жалобы
A6: 2. Общий осмотр (осмотр, пальпация, перкуссия, аускультация)
A7: 3. Лабораторные методы обследования
A8: 4. Инструментальные методы обследования
A10: Опционально
A11: Факторы риска
A12: История заболевания (анамнез морби)
A13: История жизни (анамнез витэ)
A14: Наследственность
... A28: 7. Аденомы легких
A29: 8. ХОБЛ | B29: ????
A32: Два типа пневмоний или абсцесс
A35: Формы туберкулеза: очаговая, инфильтративная, диссеменированная, кавернозная, фиброзно-кавернозная, казеозная пневмония, милиарный туберкулез, туберкулема, …
A38: Писать ли норму для анализов крови, потому что она разная для м и ж

Sheet Чек-лист
A1: Заболевание | B1: elibrary | C1: Киберленинка | D1: Pubmed | E1: Запрос
A2: Туберкулез | B2: + | C2: + | E2: туберкулез легких
A3: Туберкулез | B3: + | C3: + | E3: диагностика туберкулеза легких
A4: Туберкулез | B4: + | C4: + | E4: туберкулез органов дыхания
A5: Рак легких | C5: + | E5: рак легких
A6: Рак легких | E6: диагностика рака легких
A7: Рак легких | D7: + | E7: lung cancer diagnosis
A8: Бактериальная пневмония | C8: + | E8: бактериальная пневмония
A9: Бактериальная пневмония | C9: + | E9: диагностика бактериальная пневмония !детей !дети !ВИЧ
A10: Бактериальная пневмония | C10: + | E10: бактериальные инфекции дыхательных путей
A11: Вирусная пневмония | C11: + | E11: вирусная пневмония
A12: Вирусная пневмония | D12: + | E12: viral pneumonia

Sheet Справочники
A1: Раздел | B1: Исследование | C1: Расшифровка
A2: Жалобы | B2: Опрос
A3: Общий осмотр | B3: Осмотр
A4: Лабораторные методы обследования | B4: Пальпация
A5: Инструментальные методы обследования | B5: Перкуссия
A6: Факторы риска | B6: Аускультация
B7: Общий анализ крови
B8: Биохимический анализ крови
B9: КТ ОГК | C9: КТ органов грудной клетки
B10: МРТ
B11: Рентгенография ОГК | C11: Рентгенография органов грудной клетки
B12: ПЭТ КТ
B13: ОФЭКТ | C13: Однофотонная эмиссионная КТ
B14: Сцинтиграфия
B15: Фибробронхоскопия
B16: Общий анализ мочи
B17: Коагулограмма
B18: Гистология ???
B19: ЭКГ
B20: КТ-ангиография

Sheet Пневмония бак
A1: Раздел | B1: Признак | C1: Атрибут | D1: Значение (характеристика) | E1: Исследование | F1: Комментарии | G1: Вставила | H1: Источник
A2: Жалобы | B2: боль | C2: локазлизация | D2: грудная клетка | E2: Опрос | F2: связана с дыханием | G2: 1 | H2: Клинические рекомендации
A3: Жалобы | B3: лихорадка | C3: температура тела | D3: >38 С | E3: Опрос | G3: 1 | H3: Клинические рекомендации
A4: Жалобы | B4: слабость | C4: наличие | D4: есть | E4: Опрос | G4: 1 | H4: Клинические рекомендации
A5: Жалобы | B5: утомляемость | C5: наличие | D5: есть | E5: Опрос | G5: 1 | H5: Клинические рекомендации
A6: Жалобы | B6: озноб | C6: наличие | D6: есть | E6: Опрос | G6: 1 | H6: Клинические рекомендации
A7: Жалобы | B7: потоотделение | C7: время | D7: ночь | E7: Опрос | G7: 1 | H7: Клинические рекомендации
A8: Жалобы | B8: мокрота | C8: характер | D8: слизистая | E8: Опрос
A9: Жалобы | B9: мокрота | C9: характер | D9: "ржавая" | E9: Опрос
A10: Жалобы | B10: мокрота | C10: характер | D10: слизисто-гнойная | E10: Опрос
A11: Жалобы | B11: синдром интоксикации | C11: сонливость | E11: Опрос | G11: 1 | H11: Клинические рекомендации
A12: Жалобы | B12: синдром интоксикации | C12: беспокойство | E12: Опрос | G12: 1 | H12: Клинические рекомендации
A13: Жалобы | B13: синдром интоксикации | C13: спутанность сознания | E13: Опрос | G13: 1 | H13: Клинические рекомендации
A14: Жалобы | B14: синдром интоксикации | C14: анорексия | E14: Осмотр | G14: 1 | H14: Клинические рекомендации
A15: Жалобы | B15: синдром интоксикации | C15: тошнота | E15: Опрос | G15: 1 | H15: Клинические рекомендации
A16: Жалобы | B16: синдром интоксикации | C16: рвота | E16: Опрос | G16: 1 | H16: Клинические рекомендации
A17: Жалобы | B17: диарея | C17: наличие | D17: есть | E17: Опрос | F17: х-на для легионеллезной ВП | G17: 1 | H17: Клинические рекомендации
A18: Общий осмотр | B18: дыхательная недостаточность | C18: наличие | D18: есть | E18: - | F18: при тяжелой ВП | G18: - | H18: Клинические рекомендации
A19: Общий осмотр | B19: шок | C19: тип | D19: септический | E19: - | F19: при тяжелой ВП | G19: - | H19: Клинические рекомендации
A20: Инструментальные методы обследования | B20: инфильтрация | C20: характер | D20: очаговая | E20: Рентгенография ОГК | G20: 1 | H20: Клинические рекомендации
A21: Лабораторные методы обследования | B21: ОАК | C21: лейкоциты | D21: повышены ( > 10х10 9/л) | E21: Общий анализ крови | F21: высокая вероятность бак инфекции | G21: 1 | H21: Клинические рекомендации
A22: Лабораторные методы обследования | B22: ОАК | C22: лейкоцитарная формула | D22: палочкоядерный сдвиг (> 10%) | E22: Общий анализ крови | F22: высокая вероятность бак инфекции | G22: 1 | H22: Клинические рекомендации
A23: Общий осмотр | B23: дыхание | C23: характер | D23: бронхиальное | E23: Аускультация | G23: 1 | H23: Клинические рекомендации
A24: Общий осмотр | B24: перкуссия | C24: звук | D24: укорочение (притупление) | E24: Перкуссия | G24: 1 | H24: Клинические рекомендации
A25: Общий осмотр | B25: хрипы | C25: размер | D25: мелкопузырчатые | E25: Аускультация | G25: 1 | H25: Клинические рекомендации
A26: Общий осмотр | B26: крепитация | C26: наличие | D26: есть | E26: Аускультация | G26: 1 | H26: Клинические рекомендации
A27: Общий осмотр | B27: бронхофония | C27: характер | D27: усилена | E27: Аускультация | G27: 1 | H27: Клинические рекомендации
A28: Общий осмотр | B28: голосовое дрожание | C28: характер | D28: усилено | E28: Пальпация | G28: 1 | H28: Клинические рекомендации
A29: Общий осмотр | B29: отставание грудной клетки при дыхании | C29: локализация | D29: пораженная сторона | E29: Осмотр | G29: 1 | H29: Клинические рекомендации
A30: Лабораторные методы обследования | B30: ОАК | C30: нейтрофилы | D30: повышение | E30: Общий анализ крови | F30: высокая вероятность бак инфекции | G30: 1 | H30: Клинические рекомендации
A31: Лабораторные методы обследования | B31: ОАК | C31: нейтрофильно-лейкоцитарное соотношение | D31: >20 | E31: Общий анализ крови | F31: высокая вероятность бак инфекции | G31: 1 | H31: Клинические рекомендации
A32: Лабораторные методы обследования | B32: биохимический анализ крови | C32: СРБ | D32: повышение () | E32: Биохимический анализ крови | G32: 1 | H32: Клинические рекомендации
A33: Лабораторные методы обследования | B33: биохимический анализ крови | C33: СРБ | D33: >100 мг/л | E33: Биохимический анализ крови | F33: специфичность в подтверждении диагноза пневмония 90% | G33: 1 | H33: Клинические рекомендации
A34: Лабораторные методы обследования | B34: биохимический анализ крови | C34: СРБ | D34: <20 мг/л | E34: Биохимический анализ крови | F34: пневмония маловероятна | G34: 1 | H34: Клинические рекомендации
A35: Лабораторные методы обследования | B35: биохимический анализ крови | C35: прокальцитонин | D35: 0,5 нг/мл | E35: Биохимический анализ крови | F35: отрезная точка для дифдиагностики бак и вир пневмонии | G35: 1 | H35: Клинические рекомендации
A36: Лабораторные методы обследования | B36: Бактериоскопия мокроты | C36: бактерии | D36: обнаружены | E36: микроскопия окрашенного препарата мокроты (по Граму) | F36: для госпитализарованных паципентов (для амбулаторных не актуально) | G36: 1 | H36: Клинические рекомендации
A37: Лабораторные методы обследования | B37: Культуральное исследование плевральной ж-ти на аэробные и факультативно-аэробные м/о | C37: бактерии | D37: обнаружены | E37: Культуральный метод | F37: для госпитализированных | G37: 1 | H37: Клинические рекомендации
A38: Инструментальные методы обследования | B38: инфильтрация легочной ткани | C38: тип | D38: альвеолярный | E38: Ретгенографи ОГК | F38: плевропневмония (чаще для бактерий, особенно пневмококка) | G38: 1 | H38: Клинические рекомендации
A39: Инструментальные методы обследования | B39: инфильтрация легочной ткани | C39: тип | D39: интерстициальный (матовое стекло) | E39: Ретгенографи ОГК | F39: чаще при небактериальных пневмониях | G39: 1 | H39: Клинические рекомендации
A40: Инструментальные методы обследования | B40: инфильтрация легочной ткани | C40: тип | D40: интерстициальный (матовое стекло) | E40: КТ ОГК | F40: чаще при небактериальных пневмониях | G40: 1 | H40: Клинические рекомендации
...

Sheet Пневмония вир
A1: Раздел | B1: Признак | C1: Атрибут | D1: Значение (характеристика) | E1: Исследование | F1: Вставила | G1: Источник | H1: Комментарии
A2: Жалобы | B2: одышка | C2: характер | D2: инспираторный | E2: Опрос | F2: 0 | G2: Небактериальные маски пневмоний в клинической практике терапевта | H2: в тяжелых случая
A3: Жалобы | B3: одышка | C3: характер | D3: смешанный | E3: Опрос | F3: 0 | G3: Небактериальные маски пневмоний в клинической практике терапевта | H3: в тяжелых случаях
A4: Жалобы | B4: боль | C4: локализация | D4: грудная клетка | E4: Опрос | F4: 1 | G4: Небактериальные маски пневмоний в клинической практике терапевта
A5: Жалобы | B5: кровохарканье | C5: наличие | D5: есть | E5: Опрос | F5: 1 | G5: Небактериальные маски пневмоний в клинической практике терапевта | H5: реже, чем при бактериальной
A6: Жалобы | B6: кашель | C6: характер | D6: сухой | E6: Опрос | F6: 1 | G6: Небактериальные маски пневмоний в клинической практике терапевта | H6: в начале заболевания
A7: Жалобы | B7: кашель | C7: характер | D7: непродуктивный | E7: Опрос | F7: 1 | G7: Вирусные пневмонии новый взгляд на старую проблему
A8: Жалобы | B8: мокрота | C8: характер | D8: слизистая | E8: Опрос | F8: 1 | G8: Небактериальные маски пневмоний в клинической практике терапевта
A9: Общий осмотр | B9: цианоз | C9: локализация | D9: губы | E9: Осмотр | F9: 1 | G9: Небактериальные маски пневмоний в клинической практике терапевта
A10: Общий осмотр | B10: цианоз | C10: локализация | D10: акроцианоз | E10: Осмотр | F10: 1 | G10: Небактериальные маски пневмоний в клинической практике терапевта
A11: Общий осмотр | B11: температура тела | C11: температура | D11: повышена (37,1 — 38 °С) - субфебрильная | E11: Осмотр | F11: 1 | G11: Небактериальные маски пневмоний в клинической практике терапевта
A12: Общий осмотр | B12: температура тела | C12: температура | D12: повышена (38-39° C) - фебрильная | E12: Осмотр | F12: 1 | G12: Небактериальные маски пневмоний в клинической практике терапевта | H12: иногда
A13: Общий осмотр | B13: перкуторный звук | C13: звук | D13: укорочение | E13: Перкуссия | F13: 1 | G13: Небактериальные маски пневмоний в клинической практике терапевта | H13: над пораженными участками
A14: Общий осмотр | B14: дыхание | C14: характер | D14: ослаблено | E14: Аускультация | F14: 1 | G14: Небактериальные маски пневмоний в клинической практике терапевта | H14: над пораженными участками
A15: Общий осмотр | B15: крепитация | C15: наличие | D15: есть | E15: Аускультация | F15: 1 | G15: Небактериальные маски пневмоний в клинической практике терапевта
A16: Общий осмотр | B16: хрипы | C16: характер | D16: влажные | E16: Аускультация | F16: 1 | G16: Небактериальные маски пневмоний в клинической практике терапевта | H16: реже
A17: Общий осмотр | B17: хрипы | C17: характер | D17: сухие | E17: Аускультация | F17: 1
A18: Общий осмотр | B18: акцент 2 тона | C18: локализация | D18: над легочной артерией | E18: Аускультация сердца | F18: 1 | G18: Небактериальные маски пневмоний в клинической практике терапевта | H18: обусловлено легочной гипертензией
A19: Общий осмотр | B19: расщепление 1 тона | C19: локализация | D19: над трикуспидальным клапаном | E19: Аускультация сердца | F19: 1 | G19: Небактериальные маски пневмоний в клинической практике терапевта | H19: обусловлено легочной гипертензией
A20: Лабораторная диагностика | B20: ОАК | C20: лейкоциты | D20: снижение () - лейкопения | E20: Общий анализ крови | F20: 1 | G20: Небактериальные маски пневмоний в клинической практике терапевта
A21: Лабораторная диагностика | B21: ОАК | C21: нейтрофилы | D21: снижение () - нейтропения | E21: Общий анализ крови | F21: 1 | G21: Небактериальные маски пневмоний в клинической практике терапевта
A22: Лабораторная диагностика | B22: ОАК | C22: лимфоциты | D22: повышение () - абсолютный лимфоцитоз | E22: Общий анализ крови | F22: 1 | G22: Небактериальные маски пневмоний в клинической практике терапевта
A23: Лабораторная диагностика | B23: ОАК | C23: моноциты | D23: повышение () - моноцитоз | E23: Общий анализ крови | F23: 1 | G23: Небактериальные маски пневмоний в клинической практике терапевта
A24: Лабораторная диагностика | B24: ОАК | C24: СОЭ | D24: нормальная | E24: Общий анализ крови | F24: 1 | G24: Небактериальные маски пневмоний в клинической практике терапевта
A25: Лабораторная диагностика | B25: ОАК | C25: СОЭ | D25: повышенная | E25: Общий анализ крови | F25: 1 | G25: Небактериальные маски пневмоний в клинической практике терапевта
A26: Инструментальные методы диагностики | B26: сатурация крови кислородом | C26: сатурация | D26: пониженная () - гипоксемия | E26: Пульсоксиметрия | F26: 1 | G26: Небактериальные маски пневмоний в клинической практике терапевта
A27: Инструментальные методы диагностики | B27: корни легких | C27: размер | D27: расширены | E27: Рентгенограмма ОГК в двух проекциях | F27: 1 | G27: Небактериальные маски пневмоний в клинической практике терапевта
A28: Инструментальные методы диагностики | B28: легочные поля | C28: характер | D28: консолидированные | E28: Рентгенограмма ОГК в двух проекциях | F28: 1 | G28: Небактериальные маски пневмоний в клинической практике терапевта
A29: Инструментальные методы диагностики | B29: легочные поля | C29: характер | D29: сетчатые | E29: Рентгенограмма ОГК в двух проекциях | F29: 1 | G29: Небактериальные маски пневмоний в клинической практике терапевта
A30: Инструментальные методы диагностики | B30: легочные поля | C30: плотность | D30: повышенная | E30: Рентгенограмма ОГК в двух проекциях | F30: 1 | G30: Небактериальные маски пневмоний в клинической практике терапевта
A31: Инструментальные методы диагностики | B31: легочный рисунок | C31: характер | D31: усилен | E31: Рентгенограмма ОГК в двух проекциях | F31: 1 | G31: Небактериальные маски пневмоний в клинической практике терапевта
A32: Инструментальные методы диагностики | B32: "матовое стекло" | C32: распространение | D32: долевое | E32: КТ легких | F32: 1 | G32: Небактериальные маски пневмоний в клинической практике терапевта
A33: Инструментальные методы диагностики | B33: симптом "воздушной бронхограммы" | C33: наличие | D33: есть | E33: Рентгенограмма ОГК в двух проекциях | F33: 1
A34: Инструментальные методы диагностики | B34: "матовое стекло" | C34: распространение | D34: диффузное | E34: КТ легких | F34: 1 | G34: Небактериальные маски пневмоний в клинической практике терапевта
A35: Инструментальные методы диагностики | B35: междольковые септы | C35: размер | D35: утолщены | E35: КТ легких | F35: 1 | G35: Небактериальные маски пневмоний в клинической практике терапевта
A36: Инструментальные методы диагностики | B36: очаги | C36: размер | D36: маленький | E36: КТ легких | F36: 1 | G36: Вирусные пневмонии. Радиологические признаки сложности диагностики | H36: чем меньше очаг, тем больше вероятность вирусного происхождения
A37: Инструментальные методы диагностики | B37: легочная ткань | C37: пневмотизация | D37: снижена диффузно в виде "матового стекла" | E37: КТ легких | F37: 1 | G37: Вирусные пневмонии. Радиологические признаки сложности диагностики | H37: двустороннее снижение - признак гриппозной пневмонии
A38: Инструментальные методы диагностики | B38: легочная ткань | C38: пневмотизация | D38: уплотнена неравномерно по типу "мозаичной перфузии" | E38: КТ легких | F38: 1 | G38: Вирусные пневмонии. Радиологические признаки сложности диагностики
A39: Инструментальные методы диагностики | B39: симптом патологической исчерченности | C39: наличие | D39: есть | E39: КТ легких | F39: 1 | G39: Вирусные пневмонии. Радиологические признаки сложности диагностики | H39: синоним: симптом "булыжной мостовой"
A40: Факторы риска | B40: возраст | C40: возраст | D40: старше 65 лет | E40: Опрос | F40: 1 | G40: Вирусные пневмонии. Радиологические признаки сложности диагностики
...

Sheet Рак легких
A1: Раздел | B1: Признак | C1: Атрибут | D1: Значение (характеристика) | E1: Исследование | F1: Источник | G1: Вставила | H1: Комментарии
A2: Факторы риска | B2: пол | C2: пол | D2: мужской | E2: Опрос | F2: Рекомендации по ранней диагностике рака лёгкого для врачей первичного звена | G2: 1
A3: Факторы риска | B3: курение | C3: характеристика | D3: активное | E3: Опрос | F3: Рекомендации по ранней диагностике рака лёгкого для врачей первичного звена | G3: -
A4: Факторы риска | B4: курение | C4: характеристика | D4: пассивное | E4: Опрос | F4: Рекомендации по ранней диагностике рака лёгкого для врачей первичного звена | G4: -
A5: Факторы риска | B5: курение | C5: продолжительность | D5: более 30 лет | E5: Опрос | F5: Рекомендации по ранней диагностике рака лёгкого для врачей первичного звена | G5: -
A6: Факторы риска | B6: курение | C6: в настоящее время | D6: да | E6: Опрос | F6: Current and Future Development in Lung Cancer Diagnosis | G6: -
A7: Факторы риска | B7: курение | C7: в настоящее время | D7: нет (бросил <15 лет назад) | E7: Опрос | F7: Current and Future Development in Lung Cancer Diagnosis | G7: -
A8: Факторы риска | B8: вдыхание радона | C8: концентрация | D8: более 4 пкюри/л | E8: Опрос | F8: Рекомендации по ранней диагностике рака лёгкого для врачей первичного звена | G8: 1
A9: Факторы риска | B9: ХОБЛ | C9: стадия | D9: III-IV ст. | E9: Опрос | F9: Рекомендации по ранней диагностике рака лёгкого для врачей первичного звена | G9: 1
A10: Факторы риска | B10: работа | C10: отрасль | D10: газификация и коксование | E10: Опрос | F10: Рекомендации по ранней диагностике рака лёгкого для врачей первичного звена | G10: 1
A11: Факторы риска | B11: работа | C11: отрасль | D11: алюминиевая промышленность | E11: Опрос | F11: Рекомендации по ранней диагностике рака лёгкого для врачей первичного звена | G11: 1
A12: Факторы риска | B12: работа | C12: отрасль | D12: добыча гематита | E12: Опрос | F12: Рекомендации по ранней диагностике рака лёгкого для врачей первичного звена | G12: 1
A13: Факторы риска | B13: работа | C13: отрасль | D13: литейная промышленность | E13: Опрос | F13: Рекомендации по ранней диагностике рака лёгкого для врачей первичного звена | G13: 1
A14: Факторы риска | B14: работа | C14: отрасль | D14: производство изопропилового спирта | E14: Опрос | F14: Рекомендации по ранней диагностике рака лёгкого для врачей первичного звена | G14: 1
A15: Факторы риска | B15: работа | C15: отрасль | D15: производство фуксина | E15: Опрос | F15: Рекомендации по ранней диагностике рака лёгкого для врачей первичного звена | G15: 1
A16: Факторы риска | B16: работа | C16: отрасль | D16: резиновая промышленность | E16: Опрос | F16: Рекомендации по ранней диагностике рака лёгкого для врачей первичного звена | G16: 1
A17: Факторы риска | B17: постоянный контакт | C17: вещество | D17: асбест | E17: Опрос | F17: Рекомендации по ранней диагностике рака лёгкого для врачей первичного звена | G17: 1
A18: Факторы риска | B18: постоянный контакт | C18: вещество | D18: бериллий | E18: Опрос | F18: Рекомендации по ранней диагностике рака лёгкого для врачей первичного звена | G18: 1
A19: Факторы риска | B19: постоянный контакт | C19: вещество | D19: винилхлорид | E19: Опрос | F19: Рекомендации по ранней диагностике рака лёгкого для врачей первичного звена | G19: 1
... A33: Жалобы | B33: состояние | C33: аппетит | D33: снижение | E33: Опрос | F33: Рекомендации по ранней диагностике рака лёгкого для врачей первичного звена | G33: 1
A34: Жалобы | B34: вес | C34: изменение | D34: похудание | E34: Опрос | F34: Рекомендации по ранней диагностике рака лёгкого для врачей первичного звена | G34: 1 | H34: степень???
A35: Жалобы | B35: повышение температуры тела | C35: продолжительность | D35: не менее месяца | E35: Опрос | F35: Рекомендации по ранней диагностике рака лёгкого для врачей первичного звена | G35: 1
A36: Жалобы | B36: интоксикация | C36: продолжительность | D36: не менее месяца | E36: Опрос | F36: Рекомендации по ранней диагностике рака лёгкого для врачей первичного звена | G36: -
A37: Жалобы | B37: кашель | C37: характер | D37: сухой | E37: Опрос | F37: Рекомендации по ранней диагностике рака лёгкого для врачей первичного звена | G37: 1 | H37: при центральном раке
A38: Жалобы | B38: кашель | C38: примесь | D38: мокрота | E38: Опрос | F38: Рекомендации по ранней диагностике рака лёгкого для врачей первичного звена | G38: 1
A39: Жалобы | B39: кашель | C39: примесь | D39: кровь | E39: Опрос | F39: Рекомендации по ранней диагностике рака лёгкого для врачей первичного звена | G39: 1
A40: Жалобы | B40: одышка | C40: наличие | D40: есть | E40: Опрос | F40: Рекомендации по ранней диагностике рака лёгкого для врачей первичного звена | G40: 1
A41: Жалобы | B41: голос | C41: характер | D41: осиплый | E41: Опрос | F41: Рекомендации по ранней диагностике рака лёгкого для врачей первичного звена | G41: 1
A42: Жалобы | B42: боль | C42: локализация | D42: грудная клетка | E42: Опрос | F42: Рекомендации по ранней диагностике рака лёгкого для врачей первичного звена | G42: 1
A43: Общий осмотр | B43: кожные покровы | C43: цвет | D43: цианоз | E43: Осмотр | F43: Рекомендации по ранней диагностике рака лёгкого для врачей первичного звена | G43: 1
A44: Общий осмотр | B44: лицо | C44: состояние | D44: одутловатость | E44: Осмотр | F44: Рекомендации по ранней диагностике рака лёгкого для врачей первичного звена | G44: 1
A45: Общий осмотр | B45: вены лица и шеи | C45: состояние | D45: набухание | E45: Осмотр | F45: Рекомендации по ранней диагностике рака лёгкого для врачей первичного звена | G45: 1
A46: Факторы риска | B46: лучевая терапия | C46: на грудную клетку | D46: в анамнезе | E46: Опрос | F46: Злокачественное новообразование бронхов и легкого | G46: 1
A47: Жалобы | B47: кашель | C47: характер | D47: надсадный | E47: Опрос | F47: Злокачественное новообразование бронхов и легкого | G47: 1 | H47: центральный рак
A48: Жалобы | B48: кровохарканье | C48: наличие | D48: есть | E48: Опрос | F48: Злокачественное новообразование бронхов и легкого | G48: 1
A49: Жалобы | B49: боль в грудной клетке | C49: локализация | D49: на стороне поражения | E49: Опрос | F49: Злокачественное новообразование бронхов и легкого | G49: -
A50: Лабораторные методы обследования | B50: нейронспецифическая енолаза | C50: значение | D50: повышена 16,4 - 1000 нг/мл) | E50: Анализ на онкомаркеры | F50: Злокачественное новообразование бронхов и легкого | G50: 1 | H50: при МРЛ
A51: Лабораторные методы обследования | B51: растворимый фрагмент цитокератина 19 (CYFRA 21-1) в крови | C51: повышен | D51: 2,1-1000 нг/мл. | E51: Анализ на онкомаркеры | F51: Злокачественное новообразование бронхов и легкого | G51: 1
A52: Лабораторные методы обследования | B52: CYFRA 21-1 в крови | C52: повышен | D52: 2,1-1000 нг/мл. | E52: Анализ на онкомаркеры | F52: Злокачественное новообразование бронхов и легкого | G52: 1 | H52: при аденокарциноме
A53: Лабораторные методы обследования | B53: антиген раковый CA-125 в крови | C53: повышен | D53: 36-1000 Ед/мл | E53: Анализ на онкомаркеры | F53: Злокачественное новообразование бронхов и легкого | G53: 1 | H53: при аденокарциноме
...

Sheet Туберкулез
A1: Раздел | B1: Признак | C1: Атрибут | D1: Значение (характеристика) | E1: Исследование | F1: Источник | G1: Комментарии
A2: Жалобы | B2: кашель | C2: характер | D2: влажный (продуктивный) | E2: Опрос | F2: Туберкулез легких в пульмонологической практике
A3: Жалобы | B3: кашель | C3: характер | D3: сухой (непродуктивный) | E3: Опрос | F3: Туберкулез легких в пульмонологической практике | G3: более часто, чем влажный
A4: Жалобы | B4: боль | C4: локализация | D4: грудная клетка | E4: Опрос | F4: Туберкулез легких в пульмонологической практике
A5: Жалобы | B5: одышка | C5: наличие | D5: есть | E5: Опрос | F5: Туберкулез легких в пульмонологической практике
A6: Общий осмотр | B6: боль | C6: локализация | D6: мышцы плечевого пояса | E6: Пальпация
A7: Общий осмотр | B7: ригидность мышц | C7: локализация | D7: плечевой пояс | E7: Пальпация
A8: Общий осмотр | B8: укорочение перкуторного звука | C8: локализация | D8: надключичные пространства | E8: Перкуссия
A9: Общий осмотр | B9: укорочение перкуторного звука | D9: подключичные пространства | E9: Перкуссия
A10: Общий осмотр | B10: укорочение перкуторного звука | D10: надлопаточная область | E10: Перкуссия
A11: Общий осмотр | B11: укорочение перкуторного звука | D11: межлопаточная область | E11: Перкуссия
A12: Общий осмотр | B12: укорочение перкуторного звука | D12: подмышечная область | E12: Перкуссия
A13: Факторы риска | B13: пол | C13: пол | D13: мужской | E13: Опрос | F13: Туберкулез легких в пульмонологической практике
A14: Факторы риска | B14: социальный статус | D14: безработный | E14: Опрос | F14: Туберкулез легких в пульмонологической практике
A15: Лабораторные методы обследования | B15: наличие МБТ в мокроте | C15: МБТ | D15: обнаружено | E15: Бактериоскопия мокроты с окраской по Цилю-Нильсену | F15: Туберкулез легких в пульмонологической практике
A16: Лабораторные методы обследования | B16: наличие МБТ в бронхоальвеолярной жидкости | C16: МБТ | D16: обнаружено | E16: Микроскопия мазка с окраской по Цилю-Нильсену | F16: Туберкулез легких в пульмонологической практике
A17: Жалобы | B17: кровохарканье | C17: наличие | D17: есть | E17: Опрос | F17: Туберкулез у взрослых. Клинические рекомендации
A18: Жалобы | B18: ночные поты | C18: наличие | D18: есть | E18: Опрос | F18: Туберкулез у взрослых. Клинические рекомендации
A19: Жалобы | B19: потливость | C19: наличие | D19: есть | E19: Опрос | F19: Туберкулез у взрослых. Клинические рекомендации
A20: Жалобы | B20: снижение массы тела | C20: наличие | D20: есть | E20: Опрос | F20: Туберкулез у взрослых. Клинические рекомендации
A21: Жалобы | B21: головная боль | C21: наличие | D21: есть | E21: Опрос | F21: Туберкулез у взрослых. Клинические рекомендации
A22: Жалобы | B22: раздражительность | C22: наличие | D22: есть | E22: Опрос | F22: Туберкулез у взрослых. Клинические рекомендации
A23: Лабораторные методы обследования | B23: проба с аллергеном туберкулезным рекомбинантным | D23: положительная | E23: Проба с аллергеном туберкулезным рекомбинантным | F23: Туберкулез у взрослых. Клинические рекомендации
A24: Жалобы | B24: интоксикационный синдром | D24: утомляемость | E24: Опрос | F24: Туберкулез у взрослых. Клинические рекомендации
A25: Жалобы | B25: интоксикационный синдром | D25: слабость | E25: Опрос | F25: туберкулез легких в пульмонологической практике
A26: Жалобы | B26: интоксикационный синдром | D26: повышение температуры | E26: Опрос | F26: туберкулез легких в пульмонологической практике
A27: Факторы риска | B27: контакт с больными туберкулезом | C27: в анамнезе | D27: есть | E27: Опрос | F27: Диссеменированный туберкулез легких в клинической практике
A28: Инструментальные методы обследования | B28: очаговые тени | C28: размер | D28: средние | E28: Рентгенография ОГК | F28: Диссеменированный туберкулез легких в клинической практике
A29: Инструментальные методы обследования | B29: очаговые тени | C29: размер | D29: крупные | E29: Рентгенография ОГК | F29: Диссеменированный туберкулез легких в клинической практике
A30: Инструментальные методы обследования | B30: очаговые тени | C30: перифокальная реакция | D30: выражена | E30: Рентгенография ОГК | F30: Диссеменированный туберкулез легких в клинической практике
A31: Инструментальные методы обследования | B31: очаговые тени | C31: характер | D31: экссудативные | E31: Рентгенография ОГК | F31: Диссеменированный туберкулез легких в клинической практике
A32: Инструментальные методы обследования | B32: очаговые тени | C32: характер | D32: экссудативно-казеозные | E32: Рентгенография ОГК | F32: Диссеменированный туберкулез легких в клинической практике
A33: Инструментальные методы обследования | B33: очаговые тени | D33: сливающиеся | E33: Рентгенография ОГК | F33: Диссеменированный туберкулез легких в клинической практике
A34: Инструментальные методы обследования | B34: деструктивные полости | C34: расположение | D34: двустороннее | E34: Рентгенография ОГК | F34: Диссеменированный туберкулез легких в клинической практике | G34: при прогрессировании образующие полости распада
A35: Инструментальные методы обследования | B35: деструктивные полости | C35: ширина перикавитарной зоны инфильтрации | D35: неравномерная | E35: Рентгенография ОГК | F35: Диссеменированный туберкулез легких в клинической практике
A36: Инструментальные методы обследования | B36: деструктивные полости | C36: тип каверны | D36: пневмониогенный | E36: Рентгенография ОГК | F36: Диссеменированный туберкулез легких в клинической практике
A37: Инструментальные методы обследования | B37: деструктивные полости | C37: тип | D37: "штампованные" полости | E37: Рентгенография ОГК | F37: Диссеменированный туберкулез легких в клинической практике
A38: Инструментальные методы обследования | B38: лимфатические узлы | C38: размер | D38: увеличен | E38: Рентгенография ОГК | F38: Imaging in tuberculosis
A39: Инструментальные методы обследования | B39: лимфатические узлы | C39: размер | D39: увеличен | E39: КТ ОГК | F39: Imaging in tuberculosis
A40: Инструментальные методы обследования | B40: лимфатические узлы | C40: размер | D40: больше 2 см | E40: КТ ОГК | F40: Imaging in tuberculosis
...

Sheet ХОБЛ
A1: Раздел | B1: Признак | C1: Атрибут | D1: Значение | E1: Исследование | F1: Источник | G1: Комментарии
A2: Инструментальные методы обследования | B2: ОФВ1/ФЖЕЛ | C2: снижение | D2: <70% | E2: Спирометрия | F2: ХОБЛ: ключевые проблемы
A3: Общий осмотр | B3: хрипы | C3: характер | D3: дистанционные | F3: ХОБЛ: ключевые проблемы
A4: Жалобы | B4: одышка при физической нагрузке | C4: наличие | D4: есть | F4: ХОБЛ: ключевые проблемы
A5: Жалобы | B5: чувство сдавления в груди | C5: наличие | D5: есть | F5: ХОБЛ: ключевые проблемы
A6: Жалобы | B6: кашель | C6: характер | D6: продуктивный | F6: ХОБЛ: ключевые проблемы
B7: гипоксемия | F7: ХОБЛ: ключевые проблемы
B8: гиперкапния | F8: ХОБЛ: ключевые проблемы
A9: Инструментальные методы обследования | B9: пневмосклероз | C9: характер | D9: сетчатый | E9: Рентгенография ОГК | F9: Бронхоскопия в диагностике ХОБЛ
A10: Инструментальные методы обследования | B10: эмфизема | C10: наличие | D10: есть | E10: Рентгенография ОГК | F10: Бронхоскопия в диагностике ХОБЛ
A11: Инструментальные методы обследования | B11: эмфизема | C11: наличие | D11: есть | E11: КТ ОГК | F11: Бронхоскопия в диагностике ХОБЛ
A12: Инструментальные методы обследования | B12: слизистая оболочка бронхов | C12: состояние | D12: гиперемирована | E12: Бронхоскопия | F12: Бронхоскопия в диагностике ХОБЛ
A13: Инструментальные методы обследования | B13: сосудистый рисунок | C13: состояние | D13: смазан | E13: Бронхоскопия | F13: Бронхоскопия в диагностике ХОБЛ
A14: Инструментальные методы обследования | B14: секрет | C14: характер | D14: слизистые | E14: Бронхоскопия | F14: Бронхоскопия в диагностике ХОБЛ
A15: Инструментальные методы обследования | B15: слизистая оболочка бронхов | C15: цвет | D15: ярко-красный | E15: Бронхоскопия | F15: Бронхоскопия в диагностике ХОБЛ
A16: Инструментальные методы обследования | B16: сосудистый рисунок | C16: состояние | D16: не прослеживается | E16: Бронхоскопия | F16: Бронхоскопия в диагностике ХОБЛ
A17: Инструментальные методы обследования | B17: межкольцевые промежутки | C17: состояние | D17: сглажены | E17: Бронхоскопия | F17: Бронхоскопия в диагностике ХОБЛ | G17: имеются ввиду промежутки между хрящами
A18: Инструментальные методы обследования | B18: устья сегментарных бронхов | C18: размер | D18: сужены | E18: Бронхоскопия | F18: Бронхоскопия в диагностике ХОБЛ
A19: Инструментальные методы обследования | B19: устья субсегментарных бронхов | C19: размер | D19: сужены | E19: Бронхоскопия | F19: Бронхоскопия в диагностике ХОБЛ
A20: Инструментальные методы обследования | B20: секрет | C20: характер | D20: слизисто-гнойный | E20: Бронхоскопия | F20: Бронхоскопия в диагностике ХОБЛ
A21: Инструментальные методы обследования | B21: слизистая оболочка бронхов | C21: цвет | D21: багрово-синюшный цвет | E21: Бронхоскопия | F21: Бронхоскопия в диагностике ХОБЛ
A22: Инструментальные методы обследования | B22: секрет | C22: характер | D22: гнойный | E22: Бронхоскопия | F22: Бронхоскопия в диагностике ХОБЛ
A23: Инструментальные методы обследования | B23: секрет | C23: количество | D23: большое | E23: Бронхоскопия | F23: Бронхоскопия в диагностике ХОБЛ
A24: Инструментальные методы обследования | B24: дистония трахеи | C24: наличие | D24: есть | E24: Бронхоскопия | F24: Бронхоскопия в диагностике ХОБЛ
A25: Инструментальные методы обследования | B25: трахея | C25: состояние | D25: сужение | E25: Бронхоскопия | F25: Бронхоскопия в диагностике ХОБЛ
A26: Инструментальные методы обследования | B26: главные бронхи | C26: состояние | D26: сужение | E26: Бронхоскопия | F26: Бронхоскопия в диагностике ХОБЛ
A27: Инструментальные методы обследования | B27: слизистая оболочка бронхов | C27: цвет | D27: серый | E27: Бронхоскопия | F27: Бронхоскопия в диагностике ХОБЛ
A28: Инструментальные методы обследования | B28: хрящи | C28: контуры | D28: стерты | E28: Бронхоскопия | F28: Бронхоскопия в диагностике ХОБЛ
